2018-08-15 14:52:23,216 ERROR: Exception on /favicon.ico [GET] [in /Users/christopherjohnson/Desktop/GitHub052018/BackPocketSocial/BackPocketSocial/lib/python3.6/site-packages/flask/app.py:1761]
Traceback (most recent call last):
  File "/Users/christopherjohnson/Desktop/GitHub052018/BackPocketSocial/BackPocketSocial/lib/python3.6/site-packages/sqlalchemy/engine/base.py", line 1193, in _execute_context
    context)
  File "/Users/christopherjohnson/Desktop/GitHub052018/BackPocketSocial/BackPocketSocial/lib/python3.6/site-packages/sqlalchemy/engine/default.py", line 508, in do_execute
    cursor.execute(statement, parameters)
  File "/Users/christopherjohnson/Desktop/GitHub052018/BackPocketSocial/BackPocketSocial/lib/python3.6/site-packages/MySQLdb/cursors.py", line 250, in execute
    self.errorhandler(self, exc, value)
  File "/Users/christopherjohnson/Desktop/GitHub052018/BackPocketSocial/BackPocketSocial/lib/python3.6/site-packages/MySQLdb/connections.py", line 50, in defaulterrorhandler
    raise errorvalue
  File "/Users/christopherjohnson/Desktop/GitHub052018/BackPocketSocial/BackPocketSocial/lib/python3.6/site-packages/MySQLdb/cursors.py", line 247, in execute
    res = self._query(query)
  File "/Users/christopherjohnson/Desktop/GitHub052018/BackPocketSocial/BackPocketSocial/lib/python3.6/site-packages/MySQLdb/cursors.py", line 411, in _query
    rowcount = self._do_query(q)
  File "/Users/christopherjohnson/Desktop/GitHub052018/BackPocketSocial/BackPocketSocial/lib/python3.6/site-packages/MySQLdb/cursors.py", line 374, in _do_query
    db.query(q)
  File "/Users/christopherjohnson/Desktop/GitHub052018/BackPocketSocial/BackPocketSocial/lib/python3.6/site-packages/MySQLdb/connections.py", line 277, in query
    _mysql.connection.query(self, query)
_mysql_exceptions.OperationalError: (1054, "Unknown column 'user.profile_photo' in 'field list'")

The above exception was the direct cause of the following exception:

Traceback (most recent call last):
  File "/Users/christopherjohnson/Desktop/GitHub052018/BackPocketSocial/BackPocketSocial/lib/python3.6/site-packages/flask/app.py", line 2292, in wsgi_app
    response = self.full_dispatch_request()
  File "/Users/christopherjohnson/Desktop/GitHub052018/BackPocketSocial/BackPocketSocial/lib/python3.6/site-packages/flask/app.py", line 1815, in full_dispatch_request
    rv = self.handle_user_exception(e)
  File "/Users/christopherjohnson/Desktop/GitHub052018/BackPocketSocial/BackPocketSocial/lib/python3.6/site-packages/flask/app.py", line 1718, in handle_user_exception
    reraise(exc_type, exc_value, tb)
  File "/Users/christopherjohnson/Desktop/GitHub052018/BackPocketSocial/BackPocketSocial/lib/python3.6/site-packages/flask/_compat.py", line 35, in reraise
    raise value
  File "/Users/christopherjohnson/Desktop/GitHub052018/BackPocketSocial/BackPocketSocial/lib/python3.6/site-packages/flask/app.py", line 1811, in full_dispatch_request
    rv = self.preprocess_request()
  File "/Users/christopherjohnson/Desktop/GitHub052018/BackPocketSocial/BackPocketSocial/lib/python3.6/site-packages/flask/app.py", line 2087, in preprocess_request
    rv = func()
  File "/Users/christopherjohnson/Desktop/GitHub052018/BackPocketSocial/BackPocketSocial/app/main/routes.py", line 22, in before_request
    if current_user.is_authenticated:
  File "/Users/christopherjohnson/Desktop/GitHub052018/BackPocketSocial/BackPocketSocial/lib/python3.6/site-packages/werkzeug/local.py", line 347, in __getattr__
    return getattr(self._get_current_object(), name)
  File "/Users/christopherjohnson/Desktop/GitHub052018/BackPocketSocial/BackPocketSocial/lib/python3.6/site-packages/werkzeug/local.py", line 306, in _get_current_object
    return self.__local()
  File "/Users/christopherjohnson/Desktop/GitHub052018/BackPocketSocial/BackPocketSocial/lib/python3.6/site-packages/flask_login/utils.py", line 26, in <lambda>
    current_user = LocalProxy(lambda: _get_user())
  File "/Users/christopherjohnson/Desktop/GitHub052018/BackPocketSocial/BackPocketSocial/lib/python3.6/site-packages/flask_login/utils.py", line 335, in _get_user
    current_app.login_manager._load_user()
  File "/Users/christopherjohnson/Desktop/GitHub052018/BackPocketSocial/BackPocketSocial/lib/python3.6/site-packages/flask_login/login_manager.py", line 353, in _load_user
    return self._load_from_cookie(request.cookies[cookie_name])
  File "/Users/christopherjohnson/Desktop/GitHub052018/BackPocketSocial/BackPocketSocial/lib/python3.6/site-packages/flask_login/login_manager.py", line 392, in _load_from_cookie
    self.reload_user()
  File "/Users/christopherjohnson/Desktop/GitHub052018/BackPocketSocial/BackPocketSocial/lib/python3.6/site-packages/flask_login/login_manager.py", line 321, in reload_user
    user = self.user_callback(user_id)
  File "/Users/christopherjohnson/Desktop/GitHub052018/BackPocketSocial/BackPocketSocial/app/models/User.py", line 252, in load_user
    return User.query.get(int(id))
  File "/Users/christopherjohnson/Desktop/GitHub052018/BackPocketSocial/BackPocketSocial/lib/python3.6/site-packages/sqlalchemy/orm/query.py", line 887, in get
    ident, loading.load_on_pk_identity)
  File "/Users/christopherjohnson/Desktop/GitHub052018/BackPocketSocial/BackPocketSocial/lib/python3.6/site-packages/sqlalchemy/orm/query.py", line 962, in _get_impl
    return db_load_fn(self, primary_key_identity)
  File "/Users/christopherjohnson/Desktop/GitHub052018/BackPocketSocial/BackPocketSocial/lib/python3.6/site-packages/sqlalchemy/orm/loading.py", line 250, in load_on_pk_identity
    return q.one()
  File "/Users/christopherjohnson/Desktop/GitHub052018/BackPocketSocial/BackPocketSocial/lib/python3.6/site-packages/sqlalchemy/orm/query.py", line 2894, in one
    ret = self.one_or_none()
  File "/Users/christopherjohnson/Desktop/GitHub052018/BackPocketSocial/BackPocketSocial/lib/python3.6/site-packages/sqlalchemy/orm/query.py", line 2864, in one_or_none
    ret = list(self)
  File "/Users/christopherjohnson/Desktop/GitHub052018/BackPocketSocial/BackPocketSocial/lib/python3.6/site-packages/sqlalchemy/orm/query.py", line 2935, in __iter__
    return self._execute_and_instances(context)
  File "/Users/christopherjohnson/Desktop/GitHub052018/BackPocketSocial/BackPocketSocial/lib/python3.6/site-packages/sqlalchemy/orm/query.py", line 2958, in _execute_and_instances
    result = conn.execute(querycontext.statement, self._params)
  File "/Users/christopherjohnson/Desktop/GitHub052018/BackPocketSocial/BackPocketSocial/lib/python3.6/site-packages/sqlalchemy/engine/base.py", line 948, in execute
    return meth(self, multiparams, params)
  File "/Users/christopherjohnson/Desktop/GitHub052018/BackPocketSocial/BackPocketSocial/lib/python3.6/site-packages/sqlalchemy/sql/elements.py", line 269, in _execute_on_connection
    return connection._execute_clauseelement(self, multiparams, params)
  File "/Users/christopherjohnson/Desktop/GitHub052018/BackPocketSocial/BackPocketSocial/lib/python3.6/site-packages/sqlalchemy/engine/base.py", line 1060, in _execute_clauseelement
    compiled_sql, distilled_params
  File "/Users/christopherjohnson/Desktop/GitHub052018/BackPocketSocial/BackPocketSocial/lib/python3.6/site-packages/sqlalchemy/engine/base.py", line 1200, in _execute_context
    context)
  File "/Users/christopherjohnson/Desktop/GitHub052018/BackPocketSocial/BackPocketSocial/lib/python3.6/site-packages/sqlalchemy/engine/base.py", line 1413, in _handle_dbapi_exception
    exc_info
  File "/Users/christopherjohnson/Desktop/GitHub052018/BackPocketSocial/BackPocketSocial/lib/python3.6/site-packages/sqlalchemy/util/compat.py", line 203, in raise_from_cause
    reraise(type(exception), exception, tb=exc_tb, cause=cause)
  File "/Users/christopherjohnson/Desktop/GitHub052018/BackPocketSocial/BackPocketSocial/lib/python3.6/site-packages/sqlalchemy/util/compat.py", line 186, in reraise
    raise value.with_traceback(tb)
  File "/Users/christopherjohnson/Desktop/GitHub052018/BackPocketSocial/BackPocketSocial/lib/python3.6/site-packages/sqlalchemy/engine/base.py", line 1193, in _execute_context
    context)
  File "/Users/christopherjohnson/Desktop/GitHub052018/BackPocketSocial/BackPocketSocial/lib/python3.6/site-packages/sqlalchemy/engine/default.py", line 508, in do_execute
    cursor.execute(statement, parameters)
  File "/Users/christopherjohnson/Desktop/GitHub052018/BackPocketSocial/BackPocketSocial/lib/python3.6/site-packages/MySQLdb/cursors.py", line 250, in execute
    self.errorhandler(self, exc, value)
  File "/Users/christopherjohnson/Desktop/GitHub052018/BackPocketSocial/BackPocketSocial/lib/python3.6/site-packages/MySQLdb/connections.py", line 50, in defaulterrorhandler
    raise errorvalue
  File "/Users/christopherjohnson/Desktop/GitHub052018/BackPocketSocial/BackPocketSocial/lib/python3.6/site-packages/MySQLdb/cursors.py", line 247, in execute
    res = self._query(query)
  File "/Users/christopherjohnson/Desktop/GitHub052018/BackPocketSocial/BackPocketSocial/lib/python3.6/site-packages/MySQLdb/cursors.py", line 411, in _query
    rowcount = self._do_query(q)
  File "/Users/christopherjohnson/Desktop/GitHub052018/BackPocketSocial/BackPocketSocial/lib/python3.6/site-packages/MySQLdb/cursors.py", line 374, in _do_query
    db.query(q)
  File "/Users/christopherjohnson/Desktop/GitHub052018/BackPocketSocial/BackPocketSocial/lib/python3.6/site-packages/MySQLdb/connections.py", line 277, in query
    _mysql.connection.query(self, query)
sqlalchemy.exc.OperationalError: (_mysql_exceptions.OperationalError) (1054, "Unknown column 'user.profile_photo' in 'field list'") [SQL: 'SELECT user.id AS user_id, user.username AS user_username, user.email AS user_email, user.password_hash AS user_password_hash, user.`firstName` AS `user_firstName`, user.`lastName` AS `user_lastName`, user.`mobileNumber` AS `user_mobileNumber`, user.about_me AS user_about_me, user.profile_photo AS user_profile_photo, user.last_seen AS user_last_seen, user.token AS user_token, user.token_expiration AS user_token_expiration, user.last_message_read_time AS user_last_message_read_time \nFROM user \nWHERE user.id = %s'] [parameters: (1,)] (Background on this error at: http://sqlalche.me/e/e3q8)
