2018-06-18 23:49:02,357 ERROR: Exception on /auth/login [POST] [in /Users/christopherjohnson/Desktop/GitHub052018/BackPocketSocial/BackPocketSocial/lib/python3.6/site-packages/flask/app.py:1761]
Traceback (most recent call last):
  File "/Users/christopherjohnson/Desktop/GitHub052018/BackPocketSocial/BackPocketSocial/lib/python3.6/site-packages/sqlalchemy/engine/base.py", line 2158, in _wrap_pool_connect
    return fn()
  File "/Users/christopherjohnson/Desktop/GitHub052018/BackPocketSocial/BackPocketSocial/lib/python3.6/site-packages/sqlalchemy/pool.py", line 403, in connect
    return _ConnectionFairy._checkout(self)
  File "/Users/christopherjohnson/Desktop/GitHub052018/BackPocketSocial/BackPocketSocial/lib/python3.6/site-packages/sqlalchemy/pool.py", line 791, in _checkout
    fairy = _ConnectionRecord.checkout(pool)
  File "/Users/christopherjohnson/Desktop/GitHub052018/BackPocketSocial/BackPocketSocial/lib/python3.6/site-packages/sqlalchemy/pool.py", line 532, in checkout
    rec = pool._do_get()
  File "/Users/christopherjohnson/Desktop/GitHub052018/BackPocketSocial/BackPocketSocial/lib/python3.6/site-packages/sqlalchemy/pool.py", line 1196, in _do_get
    self._dec_overflow()
  File "/Users/christopherjohnson/Desktop/GitHub052018/BackPocketSocial/BackPocketSocial/lib/python3.6/site-packages/sqlalchemy/util/langhelpers.py", line 66, in __exit__
    compat.reraise(exc_type, exc_value, exc_tb)
  File "/Users/christopherjohnson/Desktop/GitHub052018/BackPocketSocial/BackPocketSocial/lib/python3.6/site-packages/sqlalchemy/util/compat.py", line 187, in reraise
    raise value
  File "/Users/christopherjohnson/Desktop/GitHub052018/BackPocketSocial/BackPocketSocial/lib/python3.6/site-packages/sqlalchemy/pool.py", line 1193, in _do_get
    return self._create_connection()
  File "/Users/christopherjohnson/Desktop/GitHub052018/BackPocketSocial/BackPocketSocial/lib/python3.6/site-packages/sqlalchemy/pool.py", line 350, in _create_connection
    return _ConnectionRecord(self)
  File "/Users/christopherjohnson/Desktop/GitHub052018/BackPocketSocial/BackPocketSocial/lib/python3.6/site-packages/sqlalchemy/pool.py", line 477, in __init__
    self.__connect(first_connect_check=True)
  File "/Users/christopherjohnson/Desktop/GitHub052018/BackPocketSocial/BackPocketSocial/lib/python3.6/site-packages/sqlalchemy/pool.py", line 674, in __connect
    connection = pool._invoke_creator(self)
  File "/Users/christopherjohnson/Desktop/GitHub052018/BackPocketSocial/BackPocketSocial/lib/python3.6/site-packages/sqlalchemy/engine/strategies.py", line 106, in connect
    return dialect.connect(*cargs, **cparams)
  File "/Users/christopherjohnson/Desktop/GitHub052018/BackPocketSocial/BackPocketSocial/lib/python3.6/site-packages/sqlalchemy/engine/default.py", line 411, in connect
    return self.dbapi.connect(*cargs, **cparams)
  File "/Users/christopherjohnson/Desktop/GitHub052018/BackPocketSocial/BackPocketSocial/lib/python3.6/site-packages/psycopg2/__init__.py", line 130, in connect
    conn = _connect(dsn, connection_factory=connection_factory, **kwasync)
psycopg2.OperationalError: could not connect to server: Connection refused
	Is the server running on host "localhost" (::1) and accepting
	TCP/IP connections on port 3305?
could not connect to server: Connection refused
	Is the server running on host "localhost" (127.0.0.1) and accepting
	TCP/IP connections on port 3305?


The above exception was the direct cause of the following exception:

Traceback (most recent call last):
  File "/Users/christopherjohnson/Desktop/GitHub052018/BackPocketSocial/BackPocketSocial/lib/python3.6/site-packages/flask/app.py", line 2292, in wsgi_app
    response = self.full_dispatch_request()
  File "/Users/christopherjohnson/Desktop/GitHub052018/BackPocketSocial/BackPocketSocial/lib/python3.6/site-packages/flask/app.py", line 1815, in full_dispatch_request
    rv = self.handle_user_exception(e)
  File "/Users/christopherjohnson/Desktop/GitHub052018/BackPocketSocial/BackPocketSocial/lib/python3.6/site-packages/flask/app.py", line 1718, in handle_user_exception
    reraise(exc_type, exc_value, tb)
  File "/Users/christopherjohnson/Desktop/GitHub052018/BackPocketSocial/BackPocketSocial/lib/python3.6/site-packages/flask/_compat.py", line 35, in reraise
    raise value
  File "/Users/christopherjohnson/Desktop/GitHub052018/BackPocketSocial/BackPocketSocial/lib/python3.6/site-packages/flask/app.py", line 1813, in full_dispatch_request
    rv = self.dispatch_request()
  File "/Users/christopherjohnson/Desktop/GitHub052018/BackPocketSocial/BackPocketSocial/lib/python3.6/site-packages/flask/app.py", line 1799, in dispatch_request
    return self.view_functions[rule.endpoint](**req.view_args)
  File "/Users/christopherjohnson/Desktop/GitHub052018/BackPocketSocial/BackPocketSocial/app/auth/routes.py", line 19, in login
    user = User.query.filter_by(username=form.username.data).first()
  File "/Users/christopherjohnson/Desktop/GitHub052018/BackPocketSocial/BackPocketSocial/lib/python3.6/site-packages/sqlalchemy/orm/query.py", line 2835, in first
    ret = list(self[0:1])
  File "/Users/christopherjohnson/Desktop/GitHub052018/BackPocketSocial/BackPocketSocial/lib/python3.6/site-packages/sqlalchemy/orm/query.py", line 2627, in __getitem__
    return list(res)
  File "/Users/christopherjohnson/Desktop/GitHub052018/BackPocketSocial/BackPocketSocial/lib/python3.6/site-packages/sqlalchemy/orm/query.py", line 2935, in __iter__
    return self._execute_and_instances(context)
  File "/Users/christopherjohnson/Desktop/GitHub052018/BackPocketSocial/BackPocketSocial/lib/python3.6/site-packages/sqlalchemy/orm/query.py", line 2956, in _execute_and_instances
    close_with_result=True)
  File "/Users/christopherjohnson/Desktop/GitHub052018/BackPocketSocial/BackPocketSocial/lib/python3.6/site-packages/sqlalchemy/orm/query.py", line 2965, in _get_bind_args
    **kw
  File "/Users/christopherjohnson/Desktop/GitHub052018/BackPocketSocial/BackPocketSocial/lib/python3.6/site-packages/sqlalchemy/orm/query.py", line 2947, in _connection_from_session
    conn = self.session.connection(**kw)
  File "/Users/christopherjohnson/Desktop/GitHub052018/BackPocketSocial/BackPocketSocial/lib/python3.6/site-packages/sqlalchemy/orm/session.py", line 1035, in connection
    execution_options=execution_options)
  File "/Users/christopherjohnson/Desktop/GitHub052018/BackPocketSocial/BackPocketSocial/lib/python3.6/site-packages/sqlalchemy/orm/session.py", line 1040, in _connection_for_bind
    engine, execution_options)
  File "/Users/christopherjohnson/Desktop/GitHub052018/BackPocketSocial/BackPocketSocial/lib/python3.6/site-packages/sqlalchemy/orm/session.py", line 409, in _connection_for_bind
    conn = bind.contextual_connect()
  File "/Users/christopherjohnson/Desktop/GitHub052018/BackPocketSocial/BackPocketSocial/lib/python3.6/site-packages/sqlalchemy/engine/base.py", line 2123, in contextual_connect
    self._wrap_pool_connect(self.pool.connect, None),
  File "/Users/christopherjohnson/Desktop/GitHub052018/BackPocketSocial/BackPocketSocial/lib/python3.6/site-packages/sqlalchemy/engine/base.py", line 2162, in _wrap_pool_connect
    e, dialect, self)
  File "/Users/christopherjohnson/Desktop/GitHub052018/BackPocketSocial/BackPocketSocial/lib/python3.6/site-packages/sqlalchemy/engine/base.py", line 1476, in _handle_dbapi_exception_noconnection
    exc_info
  File "/Users/christopherjohnson/Desktop/GitHub052018/BackPocketSocial/BackPocketSocial/lib/python3.6/site-packages/sqlalchemy/util/compat.py", line 203, in raise_from_cause
    reraise(type(exception), exception, tb=exc_tb, cause=cause)
  File "/Users/christopherjohnson/Desktop/GitHub052018/BackPocketSocial/BackPocketSocial/lib/python3.6/site-packages/sqlalchemy/util/compat.py", line 186, in reraise
    raise value.with_traceback(tb)
  File "/Users/christopherjohnson/Desktop/GitHub052018/BackPocketSocial/BackPocketSocial/lib/python3.6/site-packages/sqlalchemy/engine/base.py", line 2158, in _wrap_pool_connect
    return fn()
  File "/Users/christopherjohnson/Desktop/GitHub052018/BackPocketSocial/BackPocketSocial/lib/python3.6/site-packages/sqlalchemy/pool.py", line 403, in connect
    return _ConnectionFairy._checkout(self)
  File "/Users/christopherjohnson/Desktop/GitHub052018/BackPocketSocial/BackPocketSocial/lib/python3.6/site-packages/sqlalchemy/pool.py", line 791, in _checkout
    fairy = _ConnectionRecord.checkout(pool)
  File "/Users/christopherjohnson/Desktop/GitHub052018/BackPocketSocial/BackPocketSocial/lib/python3.6/site-packages/sqlalchemy/pool.py", line 532, in checkout
    rec = pool._do_get()
  File "/Users/christopherjohnson/Desktop/GitHub052018/BackPocketSocial/BackPocketSocial/lib/python3.6/site-packages/sqlalchemy/pool.py", line 1196, in _do_get
    self._dec_overflow()
  File "/Users/christopherjohnson/Desktop/GitHub052018/BackPocketSocial/BackPocketSocial/lib/python3.6/site-packages/sqlalchemy/util/langhelpers.py", line 66, in __exit__
    compat.reraise(exc_type, exc_value, exc_tb)
  File "/Users/christopherjohnson/Desktop/GitHub052018/BackPocketSocial/BackPocketSocial/lib/python3.6/site-packages/sqlalchemy/util/compat.py", line 187, in reraise
    raise value
  File "/Users/christopherjohnson/Desktop/GitHub052018/BackPocketSocial/BackPocketSocial/lib/python3.6/site-packages/sqlalchemy/pool.py", line 1193, in _do_get
    return self._create_connection()
  File "/Users/christopherjohnson/Desktop/GitHub052018/BackPocketSocial/BackPocketSocial/lib/python3.6/site-packages/sqlalchemy/pool.py", line 350, in _create_connection
    return _ConnectionRecord(self)
  File "/Users/christopherjohnson/Desktop/GitHub052018/BackPocketSocial/BackPocketSocial/lib/python3.6/site-packages/sqlalchemy/pool.py", line 477, in __init__
    self.__connect(first_connect_check=True)
  File "/Users/christopherjohnson/Desktop/GitHub052018/BackPocketSocial/BackPocketSocial/lib/python3.6/site-packages/sqlalchemy/pool.py", line 674, in __connect
    connection = pool._invoke_creator(self)
  File "/Users/christopherjohnson/Desktop/GitHub052018/BackPocketSocial/BackPocketSocial/lib/python3.6/site-packages/sqlalchemy/engine/strategies.py", line 106, in connect
    return dialect.connect(*cargs, **cparams)
  File "/Users/christopherjohnson/Desktop/GitHub052018/BackPocketSocial/BackPocketSocial/lib/python3.6/site-packages/sqlalchemy/engine/default.py", line 411, in connect
    return self.dbapi.connect(*cargs, **cparams)
  File "/Users/christopherjohnson/Desktop/GitHub052018/BackPocketSocial/BackPocketSocial/lib/python3.6/site-packages/psycopg2/__init__.py", line 130, in connect
    conn = _connect(dsn, connection_factory=connection_factory, **kwasync)
sqlalchemy.exc.OperationalError: (psycopg2.OperationalError) could not connect to server: Connection refused
	Is the server running on host "localhost" (::1) and accepting
	TCP/IP connections on port 3305?
could not connect to server: Connection refused
	Is the server running on host "localhost" (127.0.0.1) and accepting
	TCP/IP connections on port 3305?
 (Background on this error at: http://sqlalche.me/e/e3q8)
